
async funtion always returns a promise. 
if we throw error inside of a promise, that error will cause that promise to reject.